Workbook
Name SemanaActual: Panel!$B$4

Sheet Panel
A1: Panel de control
A2: Todo lo de esta hoja se calcula desde la hoja "Backlog". No editar nada aquí.
A4: Semana en curso | B4: =MIN(16,MAX(1,INT((TODAY()-DATE(2026,8,10))/7)+1)) -> 4 | C4: Se calcula con la fecha de hoy. La semana 1 empieza el lunes 10-08-2026.
A6: Indicadores
A7: Puntos del backlog | B7: =SUM(Backlog!$D$6:$D$36) -> 180
A8: Alcance comprometido | B8: =SUMIFS(Backlog!$D$6:$D$36,Backlog!$G$6:$G$36,"<>Fuera del compromiso") -> 164
A9: Terminados | B9: =SUMIFS(Backlog!$D$6:$D$36,Backlog!$G$6:$G$36,"Terminada") -> 99
A10: En curso | B10: =SUMIFS(Backlog!$D$6:$D$36,Backlog!$G$6:$G$36,"En curso") -> 5
A11: Pendientes comprometidos | B11: =SUMIFS(Backlog!$D$6:$D$36,Backlog!$G$6:$G$36,"No iniciada") -> 60
A12: Fuera del compromiso | B12: =SUMIFS(Backlog!$D$6:$D$36,Backlog!$G$6:$G$36,"Fuera del compromiso") -> 16
A13: Avance del compromiso | B13: =IFERROR((B9+B10*0.5)/B8,0) -> 0.61890244
A14: Adelanto sobre el ritmo esperado | B14: =ROUND($B$8*(1-SemanaActual/15),0)-($B$8-$B$9) -> 55
A16: Cierre por sprint - alimenta el burndown
A17: Hito | B17: Cerrado en el sprint | C17: Pendiente planificado | D17: Pendiente real | E17: Referencia lineal
A18: Inicio | B18: 0 | C18: =$B$8 -> 164 | D18: =$B$8 -> 164 | E18: =$B$8 -> 164
A19: Sprint 0 | B19: =SUMIFS(Backlog!$D$6:$D$36,Backlog!$F$6:$F$36,A19,Backlog!$G$6:$G$36,"Terminada") -> 26 | C19: =C18-SUMIFS(Backlog!$D$6:$D$36,Backlog!$F$6:$F$36,A19,Backlog!$G$6:$G$36,"<>Fuera del compromiso") -> 138 | D19: =IF(SemanaActual<1,NA(),D18-B19) -> 138 | E19: =$B$8*(1-1/5) -> 131.2
A20: Sprint 1 | B20: =SUMIFS(Backlog!$D$6:$D$36,Backlog!$F$6:$F$36,A20,Backlog!$G$6:$G$36,"Terminada") -> 73 | C20: =C19-SUMIFS(Backlog!$D$6:$D$36,Backlog!$F$6:$F$36,A20,Backlog!$G$6:$G$36,"<>Fuera del compromiso") -> 65 | D20: =IF(SemanaActual<4,NA(),D19-B20) -> 65 | E20: =$B$8*(1-2/5) -> 98.4
A21: Sprint 2 | B21: =SUMIFS(Backlog!$D$6:$D$36,Backlog!$F$6:$F$36,A21,Backlog!$G$6:$G$36,"Terminada") -> 0 | C21: =C20-SUMIFS(Backlog!$D$6:$D$36,Backlog!$F$6:$F$36,A21,Backlog!$G$6:$G$36,"<>Fuera del compromiso") -> 42 | D21: =IF(SemanaActual<7,NA(),D20-B21) -> #N/A | E21: =$B$8*(1-3/5) -> 65.6
A22: Sprint 3 | B22: =SUMIFS(Backlog!$D$6:$D$36,Backlog!$F$6:$F$36,A22,Backlog!$G$6:$G$36,"Terminada") -> 0 | C22: =C21-SUMIFS(Backlog!$D$6:$D$36,Backlog!$F$6:$F$36,A22,Backlog!$G$6:$G$36,"<>Fuera del compromiso") -> 24 | D22: =IF(SemanaActual<10,NA(),D21-B22) -> #N/A | E22: =$B$8*(1-4/5) -> 32.8
A23: Sprint 4 | B23: =SUMIFS(Backlog!$D$6:$D$36,Backlog!$F$6:$F$36,A23,Backlog!$G$6:$G$36,"Terminada") -> 0 | C23: =C22-SUMIFS(Backlog!$D$6:$D$36,Backlog!$F$6:$F$36,A23,Backlog!$G$6:$G$36,"<>Fuera del compromiso") -> 0 | D23: =IF(SemanaActual<13,NA(),D22-B23) -> #N/A | E23: =$B$8*(1-5/5) -> 0
A26: Estado por épica
A27: Épica | B27: Terminada | C27: En curso | D27: No iniciada | E27: Fuera del compromiso
A28: E1 · Núcleo de procesamiento geoespacial | B28: =SUMIFS(Backlog!$D$6:$D$36,Backlog!$C$6:$C$36,"E1",Backlog!$G$6:$G$36,"Terminada") -> 34 | C28: =SUMIFS(Backlog!$D$6:$D$36,Backlog!$C$6:$C$36,"E1",Backlog!$G$6:$G$36,"En curso") -> 0 | D28: =SUMIFS(Backlog!$D$6:$D$36,Backlog!$C$6:$C$36,"E1",Backlog!$G$6:$G$36,"No iniciada") -> 0 | E28: =SUMIFS(Backlog!$D$6:$D$36,Backlog!$C$6:$C$36,"E1",Backlog!$G$6:$G$36,"Fuera del compromiso") -> 0
A29: E2 · Datos de inversión pública | B29: =SUMIFS(Backlog!$D$6:$D$36,Backlog!$C$6:$C$36,"E2",Backlog!$G$6:$G$36,"Terminada") -> 8 | C29: =SUMIFS(Backlog!$D$6:$D$36,Backlog!$C$6:$C$36,"E2",Backlog!$G$6:$G$36,"En curso") -> 5 | D29: =SUMIFS(Backlog!$D$6:$D$36,Backlog!$C$6:$C$36,"E2",Backlog!$G$6:$G$36,"No iniciada") -> 5 | E29: =SUMIFS(Backlog!$D$6:$D$36,Backlog!$C$6:$C$36,"E2",Backlog!$G$6:$G$36,"Fuera del compromiso") -> 0
A30: E3 · Módulo de erosión y pertinencia | B30: =SUMIFS(Backlog!$D$6:$D$36,Backlog!$C$6:$C$36,"E3",Backlog!$G$6:$G$36,"Terminada") -> 34 | C30: =SUMIFS(Backlog!$D$6:$D$36,Backlog!$C$6:$C$36,"E3",Backlog!$G$6:$G$36,"En curso") -> 0 | D30: =SUMIFS(Backlog!$D$6:$D$36,Backlog!$C$6:$C$36,"E3",Backlog!$G$6:$G$36,"No iniciada") -> 0 | E30: =SUMIFS(Backlog!$D$6:$D$36,Backlog!$C$6:$C$36,"E3",Backlog!$G$6:$G$36,"Fuera del compromiso") -> 0
A31: E4 · Susceptibilidad a inundación | B31: =SUMIFS(Backlog!$D$6:$D$36,Backlog!$C$6:$C$36,"E4",Backlog!$G$6:$G$36,"Terminada") -> 0 | C31: =SUMIFS(Backlog!$D$6:$D$36,Backlog!$C$6:$C$36,"E4",Backlog!$G$6:$G$36,"En curso") -> 0 | D31: =SUMIFS(Backlog!$D$6:$D$36,Backlog!$C$6:$C$36,"E4",Backlog!$G$6:$G$36,"No iniciada") -> 18 | E31: =SUMIFS(Backlog!$D$6:$D$36,Backlog!$C$6:$C$36,"E4",Backlog!$G$6:$G$36,"Fuera del compromiso") -> 0
A32: E5 · Módulo térmico y urbano | B32: =SUMIFS(Backlog!$D$6:$D$36,Backlog!$C$6:$C$36,"E5",Backlog!$G$6:$G$36,"Terminada") -> 0 | C32: =SUMIFS(Backlog!$D$6:$D$36,Backlog!$C$6:$C$36,"E5",Backlog!$G$6:$G$36,"En curso") -> 0 | D32: =SUMIFS(Backlog!$D$6:$D$36,Backlog!$C$6:$C$36,"E5",Backlog!$G$6:$G$36,"No iniciada") -> 16 | E32: =SUMIFS(Backlog!$D$6:$D$36,Backlog!$C$6:$C$36,"E5",Backlog!$G$6:$G$36,"Fuera del compromiso") -> 0
A33: E6 · Presentación y experiencia de usuario | B33: =SUMIFS(Backlog!$D$6:$D$36,Backlog!$C$6:$C$36,"E6",Backlog!$G$6:$G$36,"Terminada") -> 18 | C33: =SUMIFS(Backlog!$D$6:$D$36,Backlog!$C$6:$C$36,"E6",Backlog!$G$6:$G$36,"En curso") -> 0 | D33: =SUMIFS(Backlog!$D$6:$D$36,Backlog!$C$6:$C$36,"E6",Backlog!$G$6:$G$36,"No iniciada") -> 8 | E33: =SUMIFS(Backlog!$D$6:$D$36,Backlog!$C$6:$C$36,"E6",Backlog!$G$6:$G$36,"Fuera del compromiso") -> 0
A34: E7 · Modelado predictivo | B34: =SUMIFS(Backlog!$D$6:$D$36,Backlog!$C$6:$C$36,"E7",Backlog!$G$6:$G$36,"Terminada") -> 0 | C34: =SUMIFS(Backlog!$D$6:$D$36,Backlog!$C$6:$C$36,"E7",Backlog!$G$6:$G$36,"En curso") -> 0 | D34: =SUMIFS(Backlog!$D$6:$D$36,Backlog!$C$6:$C$36,"E7",Backlog!$G$6:$G$36,"No iniciada") -> 0 | E34: =SUMIFS(Backlog!$D$6:$D$36,Backlog!$C$6:$C$36,"E7",Backlog!$G$6:$G$36,"Fuera del compromiso") -> 16
A35: E8 · Calidad, validación y cierre | B35: =SUMIFS(Backlog!$D$6:$D$36,Backlog!$C$6:$C$36,"E8",Backlog!$G$6:$G$36,"Terminada") -> 5 | C35: =SUMIFS(Backlog!$D$6:$D$36,Backlog!$C$6:$C$36,"E8",Backlog!$G$6:$G$36,"En curso") -> 0 | D35: =SUMIFS(Backlog!$D$6:$D$36,Backlog!$C$6:$C$36,"E8",Backlog!$G$6:$G$36,"No iniciada") -> 13 | E35: =SUMIFS(Backlog!$D$6:$D$36,Backlog!$C$6:$C$36,"E8",Backlog!$G$6:$G$36,"Fuera del compromiso") -> 0
A38: Datos del gráfico - no editar, salvo la columna amarilla
A39: Semana | B39: Avance esperado | C39: Plan de sprints | D39: Pendiente real | E39: Registro semanal | F39: Fecha del viernes
A40: Inicio | B40: =MAX(0,$B$8*(1-0/15)) -> 164 | C40: =$B$8 -> 164 | D40: =$B$8 -> 164
A41: 1 | B41: =MAX(0,$B$8*(1-1/15)) -> 153.06667 | C41: {=MAX(0,INDEX($C$18:$C$23,MIN(5,CEILING(1/3,1)))+(INDEX($C$18:$C$23,MIN(5,CEILING(1/3,1))+1)-INDEX($C$18:$C$23,MIN(5,CEILING(1/3,1))))*(1-3*(MIN(5,CEILING(1/3,1))-1))/3)} -> 155.33333 | D41: {=IF(E41<>"",E41,IF(1>SemanaActual,NA(),IF(1=SemanaActual,$B$8-$B$9,INDEX($D$18:$D$23,INT(1/3)+1))))} -> 164 | F41: 14-08-2026
A42: 2 | B42: =MAX(0,$B$8*(1-2/15)) -> 142.13333 | C42: {=MAX(0,INDEX($C$18:$C$23,MIN(5,CEILING(2/3,1)))+(INDEX($C$18:$C$23,MIN(5,CEILING(2/3,1))+1)-INDEX($C$18:$C$23,MIN(5,CEILING(2/3,1))))*(2-3*(MIN(5,CEILING(2/3,1))-1))/3)} -> 146.66667 | D42: {=IF(E42<>"",E42,IF(2>SemanaActual,NA(),IF(2=SemanaActual,$B$8-$B$9,INDEX($D$18:$D$23,INT(2/3)+1))))} -> 164 | F42: 21-08-2026
A43: 3 | B43: =MAX(0,$B$8*(1-3/15)) -> 131.2 | C43: {=MAX(0,INDEX($C$18:$C$23,MIN(5,CEILING(3/3,1)))+(INDEX($C$18:$C$23,MIN(5,CEILING(3/3,1))+1)-INDEX($C$18:$C$23,MIN(5,CEILING(3/3,1))))*(3-3*(MIN(5,CEILING(3/3,1))-1))/3)} -> 138 | D43: {=IF(E43<>"",E43,IF(3>SemanaActual,NA(),IF(3=SemanaActual,$B$8-$B$9,INDEX($D$18:$D$23,INT(3/3)+1))))} -> 138 | F43: 28-08-2026
A44: 4 | B44: =MAX(0,$B$8*(1-4/15)) -> 120.26667 | C44: {=MAX(0,INDEX($C$18:$C$23,MIN(5,CEILING(4/3,1)))+(INDEX($C$18:$C$23,MIN(5,CEILING(4/3,1))+1)-INDEX($C$18:$C$23,MIN(5,CEILING(4/3,1))))*(4-3*(MIN(5,CEILING(4/3,1))-1))/3)} -> 113.66667 | D44: {=IF(E44<>"",E44,IF(4>SemanaActual,NA(),IF(4=SemanaActual,$B$8-$B$9,INDEX($D$18:$D$23,INT(4/3)+1))))} -> 65 | F44: 04-09-2026
A45: 5 | B45: =MAX(0,$B$8*(1-5/15)) -> 109.33333 | C45: {=MAX(0,INDEX($C$18:$C$23,MIN(5,CEILING(5/3,1)))+(INDEX($C$18:$C$23,MIN(5,CEILING(5/3,1))+1)-INDEX($C$18:$C$23,MIN(5,CEILING(5/3,1))))*(5-3*(MIN(5,CEILING(5/3,1))-1))/3)} -> 89.333333 | D45: {=IF(E45<>"",E45,IF(5>SemanaActual,NA(),IF(5=SemanaActual,$B$8-$B$9,INDEX($D$18:$D$23,INT(5/3)+1))))} -> 65 | E45: 65 | F45: 11-09-2026
A46: 6 | B46: =MAX(0,$B$8*(1-6/15)) -> 98.4 | C46: {=MAX(0,INDEX($C$18:$C$23,MIN(5,CEILING(6/3,1)))+(INDEX($C$18:$C$23,MIN(5,CEILING(6/3,1))+1)-INDEX($C$18:$C$23,MIN(5,CEILING(6/3,1))))*(6-3*(MIN(5,CEILING(6/3,1))-1))/3)} -> 65 | D46: {=IF(E46<>"",E46,IF(6>SemanaActual,NA(),IF(6=SemanaActual,$B$8-$B$9,INDEX($D$18:$D$23,INT(6/3)+1))))} -> #N/A | F46: 18-09-2026
A47: 7 | B47: =MAX(0,$B$8*(1-7/15)) -> 87.466667 | C47: {=MAX(0,INDEX($C$18:$C$23,MIN(5,CEILING(7/3,1)))+(INDEX($C$18:$C$23,MIN(5,CEILING(7/3,1))+1)-INDEX($C$18:$C$23,MIN(5,CEILING(7/3,1))))*(7-3*(MIN(5,CEILING(7/3,1))-1))/3)} -> 57.333333 | D47: {=IF(E47<>"",E47,IF(7>SemanaActual,NA(),IF(7=SemanaActual,$B$8-$B$9,INDEX($D$18:$D$23,INT(7/3)+1))))} -> #N/A | F47: 25-09-2026
...

Sheet Carta Gantt
A1: TerraFoco - Carta Gantt
A2: Sistema de evaluación de pertinencia territorial de la inversión pública en recuperación de suelos · Región de O'Higgins
A3: Estado y avance se calculan desde la hoja «Backlog»; las barras, desde las columnas Inicio y Fin. Solo se editan Inicio, Fin y la fecha del sistema.
A5: Actividad | B5: Responsable de seguimiento | C5: Inicio | D5: Fin | E5: Semanas | F5: Estado | G5: Avance | H5: Fase 1 | L5: Fase 2 | W5: Fase 3
H6: Sprint 0 | K6: Sprint 1 | N6: Sprint 2 | Q6: Sprint 3 | T6: Sprint 4 | W6: Cierre
H7: 1 | I7: 2 | J7: 3 | K7: 4 | L7: 5 | M7: 6 | N7: 7 | O7: 8 | P7: 9 | Q7: 10 | R7: 11 | S7: 12 | T7: 13 | U7: 14 | V7: 15 | W7: 16
H8: 10/08 | I8: 17/08 | J8: 24/08 | K8: 31/08 | L8: 07/09 | M8: 14/09 | N8: 21/09 | O8: 28/09 | P8: 05/10 | Q8: 12/10 | R8: 19/10 | S8: 26/10 | T8: 02/11 | U8: 09/11 | V8: 16/11 | W8: 23/11
A9: Definición del proyecto y fuentes | B9: Equipo completo | C9: 1 | D9: 4 | E9: =COUNTIF(H9:W9,"X")+COUNTIF(H9:W9,"o") -> 4 | F9: =IF(G9>=1,"Completada",IF(G9<=0,"Pendiente","En curso")) -> Completada | G9: 1 | H9: =IF($C9="","",IF(AND(H$7>=$C9,H$7<=$D9),IF(H$7<=SemanaActual,"X","o"),"")) -> X | I9: =IF($C9="","",IF(AND(I$7>=$C9,I$7<=$D9),IF(I$7<=SemanaActual,"X","o"),"")) -> X | J9: =IF($C9="","",IF(AND(J$7>=$C9,J$7<=$D9),IF(J$7<=SemanaActual,"X","o"),"")) -> X | K9: =IF($C9="","",IF(AND(K$7>=$C9,K$7<=$D9),IF(K$7<=SemanaActual,"X","o"),"")) -> X | L9: =IF($C9="","",IF(AND(L$7>=$C9,L$7<=$D9),IF(L$7<=SemanaActual,"X","o"),"")) | M9: =IF($C9="","",IF(AND(M$7>=$C9,M$7<=$D9),IF(M$7<=SemanaActual,"X","o"),"")) | N9: =IF($C9="","",IF(AND(N$7>=$C9,N$7<=$D9),IF(N$7<=SemanaActual,"X","o"),"")) | O9: =IF($C9="","",IF(AND(O$7>=$C9,O$7<=$D9),IF(O$7<=SemanaActual,"X","o"),"")) | ... W9: =IF($C9="","",IF(AND(W$7>=$C9,W$7<=$D9),IF(W$7<=SemanaActual,"X","o"),""))
A10: Infraestructura y modelo de datos | B10: Bastián Cárcamo | C10: 2 | D10: 4 | E10: =COUNTIF(H10:W10,"X")+COUNTIF(H10:W10,"o") -> 3 | F10: =IF(SUMIFS(Backlog!$D$6:$D$36,Backlog!$H$6:$H$36,$A10)=0,"Sin historias",IF(SUMIFS(Backlog!$D$6:$D$36,Backlog!$H$6:$H$36,$A10,Backlog!$G$6:$G$36,"Fuera del compromiso")=SUMIFS(Backlog!$D$6:$D$36,Backlog!$H$6:$H$36,$A10),"Fuera del compromiso",IF(G10>=1,"Completada",IF(G10<=0,"Pendiente","En curso")))) -> Completada | G10: =IFERROR((SUMIFS(Backlog!$D$6:$D$36,Backlog!$H$6:$H$36,$A10,Backlog!$G$6:$G$36,"Terminada")+SUMIFS(Backlog!$D$6:$D$36,Backlog!$H$6:$H$36,$A10,Backlog!$G$6:$G$36,"En curso")*0.5)/SUMIFS(Backlog!$D$6:$D$36,Backlog!$H$6:$H$36,$A10),0) -> 1 | H10: =IF($C10="","",IF(AND(H$7>=$C10,H$7<=$D10),IF(H$7<=SemanaActual,"X","o"),"")) | I10: =IF($C10="","",IF(AND(I$7>=$C10,I$7<=$D10),IF(I$7<=SemanaActual,"X","o"),"")) -> X | J10: =IF($C10="","",IF(AND(J$7>=$C10,J$7<=$D10),IF(J$7<=SemanaActual,"X","o"),"")) -> X | K10: =IF($C10="","",IF(AND(K$7>=$C10,K$7<=$D10),IF(K$7<=SemanaActual,"X","o"),"")) -> X | L10: =IF($C10="","",IF(AND(L$7>=$C10,L$7<=$D10),IF(L$7<=SemanaActual,"X","o"),"")) | M10: =IF($C10="","",IF(AND(M$7>=$C10,M$7<=$D10),IF(M$7<=SemanaActual,"X","o"),"")) | N10: =IF($C10="","",IF(AND(N$7>=$C10,N$7<=$D10),IF(N$7<=SemanaActual,"X","o"),"")) | O10: =IF($C10="","",IF(AND(O$7>=$C10,O$7<=$D10),IF(O$7<=SemanaActual,"X","o"),"")) | ... W10: =IF($C10="","",IF(AND(W$7>=$C10,W$7<=$D10),IF(W$7<=SemanaActual,"X","o"),""))
A11: Pruebas automatizadas del motor | B11: Carla Morales | C11: 3 | D11: 5 | E11: =COUNTIF(H11:W11,"X")+COUNTIF(H11:W11,"o") -> 3 | F11: =IF(SUMIFS(Backlog!$D$6:$D$36,Backlog!$H$6:$H$36,$A11)=0,"Sin historias",IF(SUMIFS(Backlog!$D$6:$D$36,Backlog!$H$6:$H$36,$A11,Backlog!$G$6:$G$36,"Fuera del compromiso")=SUMIFS(Backlog!$D$6:$D$36,Backlog!$H$6:$H$36,$A11),"Fuera del compromiso",IF(G11>=1,"Completada",IF(G11<=0,"Pendiente","En curso")))) -> Completada | G11: =IFERROR((SUMIFS(Backlog!$D$6:$D$36,Backlog!$H$6:$H$36,$A11,Backlog!$G$6:$G$36,"Terminada")+SUMIFS(Backlog!$D$6:$D$36,Backlog!$H$6:$H$36,$A11,Backlog!$G$6:$G$36,"En curso")*0.5)/SUMIFS(Backlog!$D$6:$D$36,Backlog!$H$6:$H$36,$A11),0) -> 1 | H11: =IF($C11="","",IF(AND(H$7>=$C11,H$7<=$D11),IF(H$7<=SemanaActual,"X","o"),"")) | I11: =IF($C11="","",IF(AND(I$7>=$C11,I$7<=$D11),IF(I$7<=SemanaActual,"X","o"),"")) | J11: =IF($C11="","",IF(AND(J$7>=$C11,J$7<=$D11),IF(J$7<=SemanaActual,"X","o"),"")) -> X | K11: =IF($C11="","",IF(AND(K$7>=$C11,K$7<=$D11),IF(K$7<=SemanaActual,"X","o"),"")) -> X | L11: =IF($C11="","",IF(AND(L$7>=$C11,L$7<=$D11),IF(L$7<=SemanaActual,"X","o"),"")) -> o | M11: =IF($C11="","",IF(AND(M$7>=$C11,M$7<=$D11),IF(M$7<=SemanaActual,"X","o"),"")) | N11: =IF($C11="","",IF(AND(N$7>=$C11,N$7<=$D11),IF(N$7<=SemanaActual,"X","o"),"")) | O11: =IF($C11="","",IF(AND(O$7>=$C11,O$7<=$D11),IF(O$7<=SemanaActual,"X","o"),"")) | ... W11: =IF($C11="","",IF(AND(W$7>=$C11,W$7<=$D11),IF(W$7<=SemanaActual,"X","o"),""))
A12: Ingesta de fuentes satelitales y de terreno | B12: Bastián Cárcamo | C12: 3 | D12: 5 | E12: =COUNTIF(H12:W12,"X")+COUNTIF(H12:W12,"o") -> 3 | F12: =IF(SUMIFS(Backlog!$D$6:$D$36,Backlog!$H$6:$H$36,$A12)=0,"Sin historias",IF(SUMIFS(Backlog!$D$6:$D$36,Backlog!$H$6:$H$36,$A12,Backlog!$G$6:$G$36,"Fuera del compromiso")=SUMIFS(Backlog!$D$6:$D$36,Backlog!$H$6:$H$36,$A12),"Fuera del compromiso",IF(G12>=1,"Completada",IF(G12<=0,"Pendiente","En curso")))) -> Completada | G12: =IFERROR((SUMIFS(Backlog!$D$6:$D$36,Backlog!$H$6:$H$36,$A12,Backlog!$G$6:$G$36,"Terminada")+SUMIFS(Backlog!$D$6:$D$36,Backlog!$H$6:$H$36,$A12,Backlog!$G$6:$G$36,"En curso")*0.5)/SUMIFS(Backlog!$D$6:$D$36,Backlog!$H$6:$H$36,$A12),0) -> 1 | H12: =IF($C12="","",IF(AND(H$7>=$C12,H$7<=$D12),IF(H$7<=SemanaActual,"X","o"),"")) | I12: =IF($C12="","",IF(AND(I$7>=$C12,I$7<=$D12),IF(I$7<=SemanaActual,"X","o"),"")) | J12: =IF($C12="","",IF(AND(J$7>=$C12,J$7<=$D12),IF(J$7<=SemanaActual,"X","o"),"")) -> X | K12: =IF($C12="","",IF(AND(K$7>=$C12,K$7<=$D12),IF(K$7<=SemanaActual,"X","o"),"")) -> X | L12: =IF($C12="","",IF(AND(L$7>=$C12,L$7<=$D12),IF(L$7<=SemanaActual,"X","o"),"")) -> o | M12: =IF($C12="","",IF(AND(M$7>=$C12,M$7<=$D12),IF(M$7<=SemanaActual,"X","o"),"")) | N12: =IF($C12="","",IF(AND(N$7>=$C12,N$7<=$D12),IF(N$7<=SemanaActual,"X","o"),"")) | O12: =IF($C12="","",IF(AND(O$7>=$C12,O$7<=$D12),IF(O$7<=SemanaActual,"X","o"),"")) | ... W12: =IF($C12="","",IF(AND(W$7>=$C12,W$7<=$D12),IF(W$7<=SemanaActual,"X","o"),""))
A13: Motor de cálculo del modelo RUSLE | B13: Bastián Cárcamo y Antonio Lankin | C13: 4 | D13: 5 | E13: =COUNTIF(H13:W13,"X")+COUNTIF(H13:W13,"o") -> 2 | F13: =IF(SUMIFS(Backlog!$D$6:$D$36,Backlog!$H$6:$H$36,$A13)=0,"Sin historias",IF(SUMIFS(Backlog!$D$6:$D$36,Backlog!$H$6:$H$36,$A13,Backlog!$G$6:$G$36,"Fuera del compromiso")=SUMIFS(Backlog!$D$6:$D$36,Backlog!$H$6:$H$36,$A13),"Fuera del compromiso",IF(G13>=1,"Completada",IF(G13<=0,"Pendiente","En curso")))) -> Completada | G13: =IFERROR((SUMIFS(Backlog!$D$6:$D$36,Backlog!$H$6:$H$36,$A13,Backlog!$G$6:$G$36,"Terminada")+SUMIFS(Backlog!$D$6:$D$36,Backlog!$H$6:$H$36,$A13,Backlog!$G$6:$G$36,"En curso")*0.5)/SUMIFS(Backlog!$D$6:$D$36,Backlog!$H$6:$H$36,$A13),0) -> 1 | H13: =IF($C13="","",IF(AND(H$7>=$C13,H$7<=$D13),IF(H$7<=SemanaActual,"X","o"),"")) | I13: =IF($C13="","",IF(AND(I$7>=$C13,I$7<=$D13),IF(I$7<=SemanaActual,"X","o"),"")) | J13: =IF($C13="","",IF(AND(J$7>=$C13,J$7<=$D13),IF(J$7<=SemanaActual,"X","o"),"")) | K13: =IF($C13="","",IF(AND(K$7>=$C13,K$7<=$D13),IF(K$7<=SemanaActual,"X","o"),"")) -> X | L13: =IF($C13="","",IF(AND(L$7>=$C13,L$7<=$D13),IF(L$7<=SemanaActual,"X","o"),"")) -> o | M13: =IF($C13="","",IF(AND(M$7>=$C13,M$7<=$D13),IF(M$7<=SemanaActual,"X","o"),"")) | N13: =IF($C13="","",IF(AND(N$7>=$C13,N$7<=$D13),IF(N$7<=SemanaActual,"X","o"),"")) | O13: =IF($C13="","",IF(AND(O$7>=$C13,O$7<=$D13),IF(O$7<=SemanaActual,"X","o"),"")) | ... W13: =IF($C13="","",IF(AND(W$7>=$C13,W$7<=$D13),IF(W$7<=SemanaActual,"X","o"),""))
A14: Ingesta de la ejecución del SIRSD-S | B14: Carla Morales | C14: 4 | D14: 5 | E14: =COUNTIF(H14:W14,"X")+COUNTIF(H14:W14,"o") -> 2 | F14: =IF(SUMIFS(Backlog!$D$6:$D$36,Backlog!$H$6:$H$36,$A14)=0,"Sin historias",IF(SUMIFS(Backlog!$D$6:$D$36,Backlog!$H$6:$H$36,$A14,Backlog!$G$6:$G$36,"Fuera del compromiso")=SUMIFS(Backlog!$D$6:$D$36,Backlog!$H$6:$H$36,$A14),"Fuera del compromiso",IF(G14>=1,"Completada",IF(G14<=0,"Pendiente","En curso")))) -> Completada | G14: =IFERROR((SUMIFS(Backlog!$D$6:$D$36,Backlog!$H$6:$H$36,$A14,Backlog!$G$6:$G$36,"Terminada")+SUMIFS(Backlog!$D$6:$D$36,Backlog!$H$6:$H$36,$A14,Backlog!$G$6:$G$36,"En curso")*0.5)/SUMIFS(Backlog!$D$6:$D$36,Backlog!$H$6:$H$36,$A14),0) -> 1 | H14: =IF($C14="","",IF(AND(H$7>=$C14,H$7<=$D14),IF(H$7<=SemanaActual,"X","o"),"")) | I14: =IF($C14="","",IF(AND(I$7>=$C14,I$7<=$D14),IF(I$7<=SemanaActual,"X","o"),"")) | J14: =IF($C14="","",IF(AND(J$7>=$C14,J$7<=$D14),IF(J$7<=SemanaActual,"X","o"),"")) | K14: =IF($C14="","",IF(AND(K$7>=$C14,K$7<=$D14),IF(K$7<=SemanaActual,"X","o"),"")) -> X | L14: =IF($C14="","",IF(AND(L$7>=$C14,L$7<=$D14),IF(L$7<=SemanaActual,"X","o"),"")) -> o | M14: =IF($C14="","",IF(AND(M$7>=$C14,M$7<=$D14),IF(M$7<=SemanaActual,"X","o"),"")) | N14: =IF($C14="","",IF(AND(N$7>=$C14,N$7<=$D14),IF(N$7<=SemanaActual,"X","o"),"")) | O14: =IF($C14="","",IF(AND(O$7>=$C14,O$7<=$D14),IF(O$7<=SemanaActual,"X","o"),"")) | ... W14: =IF($C14="","",IF(AND(W$7>=$C14,W$7<=$D14),IF(W$7<=SemanaActual,"X","o"),""))
A15: Índice de pertinencia y publicación en la API | B15: Antonio Lankin | C15: 5 | D15: 5 | E15: =COUNTIF(H15:W15,"X")+COUNTIF(H15:W15,"o") -> 1 | F15: =IF(SUMIFS(Backlog!$D$6:$D$36,Backlog!$H$6:$H$36,$A15)=0,"Sin historias",IF(SUMIFS(Backlog!$D$6:$D$36,Backlog!$H$6:$H$36,$A15,Backlog!$G$6:$G$36,"Fuera del compromiso")=SUMIFS(Backlog!$D$6:$D$36,Backlog!$H$6:$H$36,$A15),"Fuera del compromiso",IF(G15>=1,"Completada",IF(G15<=0,"Pendiente","En curso")))) -> Completada | G15: =IFERROR((SUMIFS(Backlog!$D$6:$D$36,Backlog!$H$6:$H$36,$A15,Backlog!$G$6:$G$36,"Terminada")+SUMIFS(Backlog!$D$6:$D$36,Backlog!$H$6:$H$36,$A15,Backlog!$G$6:$G$36,"En curso")*0.5)/SUMIFS(Backlog!$D$6:$D$36,Backlog!$H$6:$H$36,$A15),0) -> 1 | H15: =IF($C15="","",IF(AND(H$7>=$C15,H$7<=$D15),IF(H$7<=SemanaActual,"X","o"),"")) | I15: =IF($C15="","",IF(AND(I$7>=$C15,I$7<=$D15),IF(I$7<=SemanaActual,"X","o"),"")) | J15: =IF($C15="","",IF(AND(J$7>=$C15,J$7<=$D15),IF(J$7<=SemanaActual,"X","o"),"")) | K15: =IF($C15="","",IF(AND(K$7>=$C15,K$7<=$D15),IF(K$7<=SemanaActual,"X","o"),"")) | L15: =IF($C15="","",IF(AND(L$7>=$C15,L$7<=$D15),IF(L$7<=SemanaActual,"X","o"),"")) -> o | M15: =IF($C15="","",IF(AND(M$7>=$C15,M$7<=$D15),IF(M$7<=SemanaActual,"X","o"),"")) | N15: =IF($C15="","",IF(AND(N$7>=$C15,N$7<=$D15),IF(N$7<=SemanaActual,"X","o"),"")) | O15: =IF($C15="","",IF(AND(O$7>=$C15,O$7<=$D15),IF(O$7<=SemanaActual,"X","o"),"")) | ... W15: =IF($C15="","",IF(AND(W$7>=$C15,W$7<=$D15),IF(W$7<=SemanaActual,"X","o"),""))
A16: Visor cartográfico y detalle intracomunal | B16: Antonio Lankin | C16: 4 | D16: 5 | E16: =COUNTIF(H16:W16,"X")+COUNTIF(H16:W16,"o") -> 2 | F16: =IF(SUMIFS(Backlog!$D$6:$D$36,Backlog!$H$6:$H$36,$A16)=0,"Sin historias",IF(SUMIFS(Backlog!$D$6:$D$36,Backlog!$H$6:$H$36,$A16,Backlog!$G$6:$G$36,"Fuera del compromiso")=SUMIFS(Backlog!$D$6:$D$36,Backlog!$H$6:$H$36,$A16),"Fuera del compromiso",IF(G16>=1,"Completada",IF(G16<=0,"Pendiente","En curso")))) -> Completada | G16: =IFERROR((SUMIFS(Backlog!$D$6:$D$36,Backlog!$H$6:$H$36,$A16,Backlog!$G$6:$G$36,"Terminada")+SUMIFS(Backlog!$D$6:$D$36,Backlog!$H$6:$H$36,$A16,Backlog!$G$6:$G$36,"En curso")*0.5)/SUMIFS(Backlog!$D$6:$D$36,Backlog!$H$6:$H$36,$A16),0) -> 1 | H16: =IF($C16="","",IF(AND(H$7>=$C16,H$7<=$D16),IF(H$7<=SemanaActual,"X","o"),"")) | I16: =IF($C16="","",IF(AND(I$7>=$C16,I$7<=$D16),IF(I$7<=SemanaActual,"X","o"),"")) | J16: =IF($C16="","",IF(AND(J$7>=$C16,J$7<=$D16),IF(J$7<=SemanaActual,"X","o"),"")) | K16: =IF($C16="","",IF(AND(K$7>=$C16,K$7<=$D16),IF(K$7<=SemanaActual,"X","o"),"")) -> X | L16: =IF($C16="","",IF(AND(L$7>=$C16,L$7<=$D16),IF(L$7<=SemanaActual,"X","o"),"")) -> o | M16: =IF($C16="","",IF(AND(M$7>=$C16,M$7<=$D16),IF(M$7<=SemanaActual,"X","o"),"")) | N16: =IF($C16="","",IF(AND(N$7>=$C16,N$7<=$D16),IF(N$7<=SemanaActual,"X","o"),"")) | O16: =IF($C16="","",IF(AND(O$7>=$C16,O$7<=$D16),IF(O$7<=SemanaActual,"X","o"),"")) | ... W16: =IF($C16="","",IF(AND(W$7>=$C16,W$7<=$D16),IF(W$7<=SemanaActual,"X","o"),""))
A17: Validación del modelo y dominio de validez | B17: Bastián Cárcamo | C17: 5 | D17: 5 | E17: =COUNTIF(H17:W17,"X")+COUNTIF(H17:W17,"o") -> 1 | F17: =IF(SUMIFS(Backlog!$D$6:$D$36,Backlog!$H$6:$H$36,$A17)=0,"Sin historias",IF(SUMIFS(Backlog!$D$6:$D$36,Backlog!$H$6:$H$36,$A17,Backlog!$G$6:$G$36,"Fuera del compromiso")=SUMIFS(Backlog!$D$6:$D$36,Backlog!$H$6:$H$36,$A17),"Fuera del compromiso",IF(G17>=1,"Completada",IF(G17<=0,"Pendiente","En curso")))) -> Completada | G17: =IFERROR((SUMIFS(Backlog!$D$6:$D$36,Backlog!$H$6:$H$36,$A17,Backlog!$G$6:$G$36,"Terminada")+SUMIFS(Backlog!$D$6:$D$36,Backlog!$H$6:$H$36,$A17,Backlog!$G$6:$G$36,"En curso")*0.5)/SUMIFS(Backlog!$D$6:$D$36,Backlog!$H$6:$H$36,$A17),0) -> 1 | H17: =IF($C17="","",IF(AND(H$7>=$C17,H$7<=$D17),IF(H$7<=SemanaActual,"X","o"),"")) | I17: =IF($C17="","",IF(AND(I$7>=$C17,I$7<=$D17),IF(I$7<=SemanaActual,"X","o"),"")) | J17: =IF($C17="","",IF(AND(J$7>=$C17,J$7<=$D17),IF(J$7<=SemanaActual,"X","o"),"")) | K17: =IF($C17="","",IF(AND(K$7>=$C17,K$7<=$D17),IF(K$7<=SemanaActual,"X","o"),"")) | L17: =IF($C17="","",IF(AND(L$7>=$C17,L$7<=$D17),IF(L$7<=SemanaActual,"X","o"),"")) -> o | M17: =IF($C17="","",IF(AND(M$7>=$C17,M$7<=$D17),IF(M$7<=SemanaActual,"X","o"),"")) | N17: =IF($C17="","",IF(AND(N$7>=$C17,N$7<=$D17),IF(N$7<=SemanaActual,"X","o"),"")) | O17: =IF($C17="","",IF(AND(O$7>=$C17,O$7<=$D17),IF(O$7<=SemanaActual,"X","o"),"")) | ... W17: =IF($C17="","",IF(AND(W$7>=$C17,W$7<=$D17),IF(W$7<=SemanaActual,"X","o"),""))
A18: Gestión con INDAP: serie histórica del SIRSD-S | B18: Carla Morales | C18: 6 | D18: 9 | E18: =COUNTIF(H18:W18,"X")+COUNTIF(H18:W18,"o") -> 4 | F18: =IF(SUMIFS(Backlog!$D$6:$D$36,Backlog!$H$6:$H$36,$A18)=0,"Sin historias",IF(SUMIFS(Backlog!$D$6:$D$36,Backlog!$H$6:$H$36,$A18,Backlog!$G$6:$G$36,"Fuera del compromiso")=SUMIFS(Backlog!$D$6:$D$36,Backlog!$H$6:$H$36,$A18),"Fuera del compromiso",IF(G18>=1,"Completada",IF(G18<=0,"Pendiente","En curso")))) -> En curso | G18: =IFERROR((SUMIFS(Backlog!$D$6:$D$36,Backlog!$H$6:$H$36,$A18,Backlog!$G$6:$G$36,"Terminada")+SUMIFS(Backlog!$D$6:$D$36,Backlog!$H$6:$H$36,$A18,Backlog!$G$6:$G$36,"En curso")*0.5)/SUMIFS(Backlog!$D$6:$D$36,Backlog!$H$6:$H$36,$A18),0) -> 0.5 | H18: =IF($C18="","",IF(AND(H$7>=$C18,H$7<=$D18),IF(H$7<=SemanaActual,"X","o"),"")) | I18: =IF($C18="","",IF(AND(I$7>=$C18,I$7<=$D18),IF(I$7<=SemanaActual,"X","o"),"")) | J18: =IF($C18="","",IF(AND(J$7>=$C18,J$7<=$D18),IF(J$7<=SemanaActual,"X","o"),"")) | K18: =IF($C18="","",IF(AND(K$7>=$C18,K$7<=$D18),IF(K$7<=SemanaActual,"X","o"),"")) | L18: =IF($C18="","",IF(AND(L$7>=$C18,L$7<=$D18),IF(L$7<=SemanaActual,"X","o"),"")) | M18: =IF($C18="","",IF(AND(M$7>=$C18,M$7<=$D18),IF(M$7<=SemanaActual,"X","o"),"")) -> o | N18: =IF($C18="","",IF(AND(N$7>=$C18,N$7<=$D18),IF(N$7<=SemanaActual,"X","o"),"")) -> o | O18: =IF($C18="","",IF(AND(O$7>=$C18,O$7<=$D18),IF(O$7<=SemanaActual,"X","o"),"")) -> o | ... W18: =IF($C18="","",IF(AND(W$7>=$C18,W$7<=$D18),IF(W$7<=SemanaActual,"X","o"),""))
A19: Validación de montos contra las series de ODEPA | B19: Carla Morales | C19: 7 | D19: 8 | E19: =COUNTIF(H19:W19,"X")+COUNTIF(H19:W19,"o") -> 2 | F19: =IF(SUMIFS(Backlog!$D$6:$D$36,Backlog!$H$6:$H$36,$A19)=0,"Sin historias",IF(SUMIFS(Backlog!$D$6:$D$36,Backlog!$H$6:$H$36,$A19,Backlog!$G$6:$G$36,"Fuera del compromiso")=SUMIFS(Backlog!$D$6:$D$36,Backlog!$H$6:$H$36,$A19),"Fuera del compromiso",IF(G19>=1,"Completada",IF(G19<=0,"Pendiente","En curso")))) -> Pendiente | G19: =IFERROR((SUMIFS(Backlog!$D$6:$D$36,Backlog!$H$6:$H$36,$A19,Backlog!$G$6:$G$36,"Terminada")+SUMIFS(Backlog!$D$6:$D$36,Backlog!$H$6:$H$36,$A19,Backlog!$G$6:$G$36,"En curso")*0.5)/SUMIFS(Backlog!$D$6:$D$36,Backlog!$H$6:$H$36,$A19),0) -> 0 | H19: =IF($C19="","",IF(AND(H$7>=$C19,H$7<=$D19),IF(H$7<=SemanaActual,"X","o"),"")) | I19: =IF($C19="","",IF(AND(I$7>=$C19,I$7<=$D19),IF(I$7<=SemanaActual,"X","o"),"")) | J19: =IF($C19="","",IF(AND(J$7>=$C19,J$7<=$D19),IF(J$7<=SemanaActual,"X","o"),"")) | K19: =IF($C19="","",IF(AND(K$7>=$C19,K$7<=$D19),IF(K$7<=SemanaActual,"X","o"),"")) | L19: =IF($C19="","",IF(AND(L$7>=$C19,L$7<=$D19),IF(L$7<=SemanaActual,"X","o"),"")) | M19: =IF($C19="","",IF(AND(M$7>=$C19,M$7<=$D19),IF(M$7<=SemanaActual,"X","o"),"")) | N19: =IF($C19="","",IF(AND(N$7>=$C19,N$7<=$D19),IF(N$7<=SemanaActual,"X","o"),"")) -> o | O19: =IF($C19="","",IF(AND(O$7>=$C19,O$7<=$D19),IF(O$7<=SemanaActual,"X","o"),"")) -> o | ... W19: =IF($C19="","",IF(AND(W$7>=$C19,W$7<=$D19),IF(W$7<=SemanaActual,"X","o"),""))
A20: Módulo 2 - susceptibilidad a inundaciones | B20: Equipo completo | C20: 8 | D20: 11 | E20: =COUNTIF(H20:W20,"X")+COUNTIF(H20:W20,"o") -> 4 | F20: =IF(SUMIFS(Backlog!$D$6:$D$36,Backlog!$H$6:$H$36,$A20)=0,"Sin historias",IF(SUMIFS(Backlog!$D$6:$D$36,Backlog!$H$6:$H$36,$A20,Backlog!$G$6:$G$36,"Fuera del compromiso")=SUMIFS(Backlog!$D$6:$D$36,Backlog!$H$6:$H$36,$A20),"Fuera del compromiso",IF(G20>=1,"Completada",IF(G20<=0,"Pendiente","En curso")))) -> Sin historias | G20: =IFERROR((SUMIFS(Backlog!$D$6:$D$36,Backlog!$H$6:$H$36,$A20,Backlog!$G$6:$G$36,"Terminada")+SUMIFS(Backlog!$D$6:$D$36,Backlog!$H$6:$H$36,$A20,Backlog!$G$6:$G$36,"En curso")*0.5)/SUMIFS(Backlog!$D$6:$D$36,Backlog!$H$6:$H$36,$A20),0) -> 0 | H20: =IF($C20="","",IF(AND(H$7>=$C20,H$7<=$D20),IF(H$7<=SemanaActual,"X","o"),"")) | I20: =IF($C20="","",IF(AND(I$7>=$C20,I$7<=$D20),IF(I$7<=SemanaActual,"X","o"),"")) | J20: =IF($C20="","",IF(AND(J$7>=$C20,J$7<=$D20),IF(J$7<=SemanaActual,"X","o"),"")) | K20: =IF($C20="","",IF(AND(K$7>=$C20,K$7<=$D20),IF(K$7<=SemanaActual,"X","o"),"")) | L20: =IF($C20="","",IF(AND(L$7>=$C20,L$7<=$D20),IF(L$7<=SemanaActual,"X","o"),"")) | M20: =IF($C20="","",IF(AND(M$7>=$C20,M$7<=$D20),IF(M$7<=SemanaActual,"X","o"),"")) | N20: =IF($C20="","",IF(AND(N$7>=$C20,N$7<=$D20),IF(N$7<=SemanaActual,"X","o"),"")) | O20: =IF($C20="","",IF(AND(O$7>=$C20,O$7<=$D20),IF(O$7<=SemanaActual,"X","o"),"")) -> o | ... W20: =IF($C20="","",IF(AND(W$7>=$C20,W$7<=$D20),IF(W$7<=SemanaActual,"X","o"),""))
A21: Exportación de reportes y comprensibilidad del visor | B21: Antonio Lankin | C21: 10 | D21: 12 | E21: =COUNTIF(H21:W21,"X")+COUNTIF(H21:W21,"o") -> 3 | F21: =IF(SUMIFS(Backlog!$D$6:$D$36,Backlog!$H$6:$H$36,$A21)=0,"Sin historias",IF(SUMIFS(Backlog!$D$6:$D$36,Backlog!$H$6:$H$36,$A21,Backlog!$G$6:$G$36,"Fuera del compromiso")=SUMIFS(Backlog!$D$6:$D$36,Backlog!$H$6:$H$36,$A21),"Fuera del compromiso",IF(G21>=1,"Completada",IF(G21<=0,"Pendiente","En curso")))) -> Pendiente | G21: =IFERROR((SUMIFS(Backlog!$D$6:$D$36,Backlog!$H$6:$H$36,$A21,Backlog!$G$6:$G$36,"Terminada")+SUMIFS(Backlog!$D$6:$D$36,Backlog!$H$6:$H$36,$A21,Backlog!$G$6:$G$36,"En curso")*0.5)/SUMIFS(Backlog!$D$6:$D$36,Backlog!$H$6:$H$36,$A21),0) -> 0 | H21: =IF($C21="","",IF(AND(H$7>=$C21,H$7<=$D21),IF(H$7<=SemanaActual,"X","o"),"")) | I21: =IF($C21="","",IF(AND(I$7>=$C21,I$7<=$D21),IF(I$7<=SemanaActual,"X","o"),"")) | J21: =IF($C21="","",IF(AND(J$7>=$C21,J$7<=$D21),IF(J$7<=SemanaActual,"X","o"),"")) | K21: =IF($C21="","",IF(AND(K$7>=$C21,K$7<=$D21),IF(K$7<=SemanaActual,"X","o"),"")) | L21: =IF($C21="","",IF(AND(L$7>=$C21,L$7<=$D21),IF(L$7<=SemanaActual,"X","o"),"")) | M21: =IF($C21="","",IF(AND(M$7>=$C21,M$7<=$D21),IF(M$7<=SemanaActual,"X","o"),"")) | N21: =IF($C21="","",IF(AND(N$7>=$C21,N$7<=$D21),IF(N$7<=SemanaActual,"X","o"),"")) | O21: =IF($C21="","",IF(AND(O$7>=$C21,O$7<=$D21),IF(O$7<=SemanaActual,"X","o"),"")) | ... W21: =IF($C21="","",IF(AND(W$7>=$C21,W$7<=$D21),IF(W$7<=SemanaActual,"X","o"),""))
... A24: Trazabilidad metodológica CRISP-DM | B24: Equipo completo | C24: 12 | D24: 15 | E24: =COUNTIF(H24:W24,"X")+COUNTIF(H24:W24,"o") -> 4 | F24: =IF(SUMIFS(Backlog!$D$6:$D$36,Backlog!$H$6:$H$36,$A24)=0,"Sin historias",IF(SUMIFS(Backlog!$D$6:$D$36,Backlog!$H$6:$H$36,$A24,Backlog!$G$6:$G$36,"Fuera del compromiso")=SUMIFS(Backlog!$D$6:$D$36,Backlog!$H$6:$H$36,$A24),"Fuera del compromiso",IF(G24>=1,"Completada",IF(G24<=0,"Pendiente","En curso")))) -> Pendiente | G24: =IFERROR((SUMIFS(Backlog!$D$6:$D$36,Backlog!$H$6:$H$36,$A24,Backlog!$G$6:$G$36,"Terminada")+SUMIFS(Backlog!$D$6:$D$36,Backlog!$H$6:$H$36,$A24,Backlog!$G$6:$G$36,"En curso")*0.5)/SUMIFS(Backlog!$D$6:$D$36,Backlog!$H$6:$H$36,$A24),0) -> 0 | H24: =IF($C24="","",IF(AND(H$7>=$C24,H$7<=$D24),IF(H$7<=SemanaActual,"X","o"),"")) | I24: =IF($C24="","",IF(AND(I$7>=$C24,I$7<=$D24),IF(I$7<=SemanaActual,"X","o"),"")) | J24: =IF($C24="","",IF(AND(J$7>=$C24,J$7<=$D24),IF(J$7<=SemanaActual,"X","o"),"")) | K24: =IF($C24="","",IF(AND(K$7>=$C24,K$7<=$D24),IF(K$7<=SemanaActual,"X","o"),"")) | L24: =IF($C24="","",IF(AND(L$7>=$C24,L$7<=$D24),IF(L$7<=SemanaActual,"X","o"),"")) | M24: =IF($C24="","",IF(AND(M$7>=$C24,M$7<=$D24),IF(M$7<=SemanaActual,"X","o"),"")) | N24: =IF($C24="","",IF(AND(N$7>=$C24,N$7<=$D24),IF(N$7<=SemanaActual,"X","o"),"")) | O24: =IF($C24="","",IF(AND(O$7>=$C24,O$7<=$D24),IF(O$7<=SemanaActual,"X","o"),"")) | ... W24: =IF($C24="","",IF(AND(W$7>=$C24,W$7<=$D24),IF(W$7<=SemanaActual,"X","o"),""))
A25: Documentación técnica versionada | B25: Equipo completo | C25: 1 | D25: 15 | E25: =COUNTIF(H25:W25,"X")+COUNTIF(H25:W25,"o") -> 15 | F25: =IF(G25>=1,"Completada",IF(G25<=0,"Pendiente","En curso")) -> En curso | G25: 0.85 | H25: =IF($C25="","",IF(AND(H$7>=$C25,H$7<=$D25),IF(H$7<=SemanaActual,"X","o"),"")) -> X | I25: =IF($C25="","",IF(AND(I$7>=$C25,I$7<=$D25),IF(I$7<=SemanaActual,"X","o"),"")) -> X | J25: =IF($C25="","",IF(AND(J$7>=$C25,J$7<=$D25),IF(J$7<=SemanaActual,"X","o"),"")) -> X | K25: =IF($C25="","",IF(AND(K$7>=$C25,K$7<=$D25),IF(K$7<=SemanaActual,"X","o"),"")) -> X | L25: =IF($C25="","",IF(AND(L$7>=$C25,L$7<=$D25),IF(L$7<=SemanaActual,"X","o"),"")) -> o | M25: =IF($C25="","",IF(AND(M$7>=$C25,M$7<=$D25),IF(M$7<=SemanaActual,"X","o"),"")) -> o | N25: =IF($C25="","",IF(AND(N$7>=$C25,N$7<=$D25),IF(N$7<=SemanaActual,"X","o"),"")) -> o | O25: =IF($C25="","",IF(AND(O$7>=$C25,O$7<=$D25),IF(O$7<=SemanaActual,"X","o"),"")) -> o | ... W25: =IF($C25="","",IF(AND(W$7>=$C25,W$7<=$D25),IF(W$7<=SemanaActual,"X","o"),""))
A26: Informe final, resultados y defensa | B26: Equipo completo | C26: 13 | D26: 16 | E26: =COUNTIF(H26:W26,"X")+COUNTIF(H26:W26,"o") -> 4 | F26: =IF(G26>=1,"Completada",IF(G26<=0,"Pendiente","En curso")) -> Pendiente | G26: 0 | H26: =IF($C26="","",IF(AND(H$7>=$C26,H$7<=$D26),IF(H$7<=SemanaActual,"X","o"),"")) | I26: =IF($C26="","",IF(AND(I$7>=$C26,I$7<=$D26),IF(I$7<=SemanaActual,"X","o"),"")) | J26: =IF($C26="","",IF(AND(J$7>=$C26,J$7<=$D26),IF(J$7<=SemanaActual,"X","o"),"")) | K26: =IF($C26="","",IF(AND(K$7>=$C26,K$7<=$D26),IF(K$7<=SemanaActual,"X","o"),"")) | L26: =IF($C26="","",IF(AND(L$7>=$C26,L$7<=$D26),IF(L$7<=SemanaActual,"X","o"),"")) | M26: =IF($C26="","",IF(AND(M$7>=$C26,M$7<=$D26),IF(M$7<=SemanaActual,"X","o"),"")) | N26: =IF($C26="","",IF(AND(N$7>=$C26,N$7<=$D26),IF(N$7<=SemanaActual,"X","o"),"")) | O26: =IF($C26="","",IF(AND(O$7>=$C26,O$7<=$D26),IF(O$7<=SemanaActual,"X","o"),"")) | ... W26: =IF($C26="","",IF(AND(W$7>=$C26,W$7<=$D26),IF(W$7<=SemanaActual,"X","o"),"")) -> o
A27: Modelado predictivo | B27: - | E27: =COUNTIF(H27:W27,"X")+COUNTIF(H27:W27,"o") -> 0 | F27: =IF(SUMIFS(Backlog!$D$6:$D$36,Backlog!$H$6:$H$36,$A27)=0,"Sin historias",IF(SUMIFS(Backlog!$D$6:$D$36,Backlog!$H$6:$H$36,$A27,Backlog!$G$6:$G$36,"Fuera del compromiso")=SUMIFS(Backlog!$D$6:$D$36,Backlog!$H$6:$H$36,$A27),"Fuera del compromiso",IF(G27>=1,"Completada",IF(G27<=0,"Pendiente","En curso")))) -> Fuera del compromiso | G27: =IFERROR((SUMIFS(Backlog!$D$6:$D$36,Backlog!$H$6:$H$36,$A27,Backlog!$G$6:$G$36,"Terminada")+SUMIFS(Backlog!$D$6:$D$36,Backlog!$H$6:$H$36,$A27,Backlog!$G$6:$G$36,"En curso")*0.5)/SUMIFS(Backlog!$D$6:$D$36,Backlog!$H$6:$H$36,$A27),0) -> 0 | H27: =IF($C27="","",IF(AND(H$7>=$C27,H$7<=$D27),IF(H$7<=SemanaActual,"X","o"),"")) | I27: =IF($C27="","",IF(AND(I$7>=$C27,I$7<=$D27),IF(I$7<=SemanaActual,"X","o"),"")) | J27: =IF($C27="","",IF(AND(J$7>=$C27,J$7<=$D27),IF(J$7<=SemanaActual,"X","o"),"")) | K27: =IF($C27="","",IF(AND(K$7>=$C27,K$7<=$D27),IF(K$7<=SemanaActual,"X","o"),"")) | L27: =IF($C27="","",IF(AND(L$7>=$C27,L$7<=$D27),IF(L$7<=SemanaActual,"X","o"),"")) | M27: =IF($C27="","",IF(AND(M$7>=$C27,M$7<=$D27),IF(M$7<=SemanaActual,"X","o"),"")) | N27: =IF($C27="","",IF(AND(N$7>=$C27,N$7<=$D27),IF(N$7<=SemanaActual,"X","o"),"")) | O27: =IF($C27="","",IF(AND(O$7>=$C27,O$7<=$D27),IF(O$7<=SemanaActual,"X","o"),"")) | ... W27: =IF($C27="","",IF(AND(W$7>=$C27,W$7<=$D27),IF(W$7<=SemanaActual,"X","o"),""))
A29: Hitos de evaluación | L29: ◆ | R29: ◆ | V29: ◆ | W29: ◆
L30: Fase 1 | R30: Fase 2 | V30: Fase 3 | W30: Defensa
A32: Actividades en paralelo | H32: =COUNTIF(H9:H27,"X")+COUNTIF(H9:H27,"o") -> 2 | I32: =COUNTIF(I9:I27,"X")+COUNTIF(I9:I27,"o") -> 3 | J32: =COUNTIF(J9:J27,"X")+COUNTIF(J9:J27,"o") -> 5 | K32: =COUNTIF(K9:K27,"X")+COUNTIF(K9:K27,"o") -> 8 | L32: =COUNTIF(L9:L27,"X")+COUNTIF(L9:L27,"o") -> 8 | M32: =COUNTIF(M9:M27,"X")+COUNTIF(M9:M27,"o") -> 2 | N32: =COUNTIF(N9:N27,"X")+COUNTIF(N9:N27,"o") -> 3 | O32: =COUNTIF(O9:O27,"X")+COUNTIF(O9:O27,"o") -> 4 | ... W32: =COUNTIF(W9:W27,"X")+COUNTIF(W9:W27,"o") -> 1
A34: Las barras se dibujan solas desde Inicio y Fin: color fuerte hasta la semana en curso, tono claro después. La semana en curso va destacada en rojo y se calcula con la fecha del sistema.

Sheet Backlog
A1: Backlog
A3: Estado válido: Terminada · En curso · No iniciada · Fuera del compromiso. La columna Sprint asigna la historia a una iteración.
A5: ID | B5: Historia de usuario | C5: Épica | D5: Pts | E5: MoSCoW | F5: Sprint | G5: Estado | H5: Actividad de la carta Gantt | I5: Responsable de seguimiento | J5: Evidencia en el repositorio
A6: HU-01 | B6: Modelo de datos espacial en PostGIS con versionado temporal | C6: E1 | D6: 8 | E6: Must | F6: Sprint 0 | G6: Terminada | H6: Infraestructura y modelo de datos | I6: Bastián Cárcamo | J6: bd/esquema.sql: 17 tablas en cuatro esquemas más cuatro migraciones numeradas. El versionado está en indicadores.erosion_r y susceptibilidad_inundacion_r
A7: HU-02 | B7: Descarga automática de imágenes Sentinel-2 | C7: E1 | D7: 8 | E7: Must | F7: Sprint 0 | G7: Terminada | H7: Ingesta de fuentes satelitales y de terreno | I7: Bastián Cárcamo | J7: motor/ingesta/sentinel.py, con composición mensual para descartar píxeles nublados
A8: HU-03 | B8: Descarga del modelo de elevación SRTM | C8: E1 | D8: 5 | E8: Must | F8: Sprint 0 | G8: Terminada | H8: Ingesta de fuentes satelitales y de terreno | I8: Bastián Cárcamo | J8: motor/ingesta/srtm.py, con opción --solo-preparar
A9: HU-04 | B9: Reproyección y recorte automáticos de los insumos | C9: E1 | D9: 8 | E9: Must | F9: Sprint 1 | G9: Terminada | H9: Ingesta de fuentes satelitales y de terreno | I9: Bastián Cárcamo | J9: motor/ingesta/zonal.py reproyecta en PostGIS y rechaza rásteres en grados; vectorial.py para las capas vectoriales. 14 casos en test_zonal.py
A10: HU-05 | B10: Consulta de la bitácora de ejecuciones | C10: E1 | D10: 5 | E10: Should | F10: Sprint 1 | G10: Terminada | H10: Infraestructura y modelo de datos | I10: Carla Morales | J10: Clase Bitacora en motor/bd.py, módulo motor/estado.py y tabla operacion.ejecucion_proceso
A11: HU-06 | B11: Consolidación de las planillas de Transparencia Activa | C11: E2 | D11: 8 | E11: Must | F11: Sprint 1 | G11: Terminada | H11: Ingesta de la ejecución del SIRSD-S | I11: Carla Morales | J11: motor/ingesta/sirsd_ide.py agrega por comuna y temporada y deriva a programas.ejecucion_rechazada lo no identificable. 17 pruebas en test_sirsd.py
A12: HU-07 | B12: Validación de los montos contra las series de ODEPA | C12: E2 | D12: 5 | E12: Should | F12: Sprint 2 | G12: No iniciada | H12: Validación de montos contra las series de ODEPA | I12: Carla Morales | J12: ODEPA solo se menciona en docs/01 y docs/05. No hay módulo ni consulta
A13: HU-08 | B13: Gestión de la solicitud de acceso a información pública | C13: E2 | D13: 5 | E13: Must | F13: Sprint 2 | G13: En curso | H13: Gestión con INDAP: serie histórica del SIRSD-S | I13: Carla Morales | J13: docs/11-solicitud-datos-indap.md redactado y gestión abierta. El servicio de IDE MINAGRI cubre un solo año
A14: HU-09 | B14: Cálculo del NDVI desde Sentinel-2 para el factor C | C14: E3 | D14: 5 | E14: Must | F14: Sprint 1 | G14: Terminada | H14: Motor de cálculo del modelo RUSLE | I14: Bastián Cárcamo | J14: motor/ingesta/sentinel.py deriva el NDVI y de ahí el factor C
A15: HU-10 | B15: Pendiente y longitud desde el SRTM para el factor LS | C15: E3 | D15: 5 | E15: Must | F15: Sprint 1 | G15: Terminada | H15: Motor de cálculo del modelo RUSLE | I15: Bastián Cárcamo | J15: motor/indicadores/terreno.py: pendiente_horn, ls_desde_pendiente, ls_de_comuna. 31 casos en test_terreno.py
A16: HU-11 | B16: Erosión estimada por comuna aplicando RUSLE | C16: E3 | D16: 8 | E16: Must | F16: Sprint 1 | G16: Terminada | H16: Motor de cálculo del modelo RUSLE | I16: Bastián Cárcamo y Antonio Lankin | J16: rusle.py y calcular.py aplican A = R·K·LS·C·P con los cinco factores alimentados por cr2met, soilgrids, zonal, sentinel y practicas
A17: HU-12 | B17: Comparación de la erosión estimada con la línea base de CIREN | C17: E3 | D17: 5 | E17: Must | F17: Sprint 1 | G17: Terminada | H17: Validación del modelo y dominio de validez | I17: Bastián Cárcamo | J17: ciren.py descarga por WFS; migraciones 003 y 004 y el campo en_dominio sostienen la comparación
... A36: HU-31 | B36: Documentación del proceso analítico según CRISP-DM | C36: E8 | D36: 3 | E36: Must | F36: Sprint 4 | G36: No iniciada | H36: Trazabilidad metodológica CRISP-DM | I36: Equipo completo | J36: CRISP-DM se menciona en docs/01 y docs/05, sin documento que deje trazabilidad de las seis fases

Sheet Sprints
A1: Planificación de sprints
A2: Seis iteraciones de tres semanas ancladas al lunes 10-08-2026. Los puntos y el estado se calculan desde la hoja "Backlog".
A5: Sprint | B5: Semanas | C5: Desde | D5: Hasta | E5: Foco | F5: Pts comprometidos | G5: Terminados | H5: Avance | I5: Incremento demostrable
A6: Sprint 0 | B6: 1 a 3 | C6: 10-08-2026 | D6: 28-08-2026 | E6: Configuración, arquitectura y modelo de datos | F6: =SUMIFS(Backlog!$D$6:$D$36,Backlog!$F$6:$F$36,$A6,Backlog!$G$6:$G$36,"<>Fuera del compromiso") -> 26 | G6: =SUMIFS(Backlog!$D$6:$D$36,Backlog!$F$6:$F$36,$A6,Backlog!$G$6:$G$36,"Terminada") -> 26 | H6: =IFERROR(G6/F6,0) -> 1 | I6: Entorno en contenedores operativo, esquema espacial migrado, descarga automática de Sentinel-2 y SRTM, y batería de pruebas en marcha
A7: Sprint 1 | B7: 4 a 6 | C7: 31-08-2026 | D7: 18-09-2026 | E7: Núcleo, módulo de erosión y cruce con la inversión | F7: =SUMIFS(Backlog!$D$6:$D$36,Backlog!$F$6:$F$36,$A7,Backlog!$G$6:$G$36,"<>Fuera del compromiso") -> 73 | G7: =SUMIFS(Backlog!$D$6:$D$36,Backlog!$F$6:$F$36,$A7,Backlog!$G$6:$G$36,"Terminada") -> 73 | H7: =IFERROR(G7/F7,0) -> 1 | I7: Cinco factores RUSLE con datos medidos para las 33 comunas, índice de pertinencia expuesto por la API y visor con cartografía real, ficha comunal y detalle de erosión por píxel
A8: Sprint 2 | B8: 7 a 9 | C8: 21-09-2026 | D8: 09-10-2026 | E8: Cierre del eje de inversión pública e inicio de inundaciones | F8: =SUMIFS(Backlog!$D$6:$D$36,Backlog!$F$6:$F$36,$A8,Backlog!$G$6:$G$36,"<>Fuera del compromiso") -> 23 | G8: =SUMIFS(Backlog!$D$6:$D$36,Backlog!$F$6:$F$36,$A8,Backlog!$G$6:$G$36,"Terminada") -> 0 | H8: =IFERROR(G8/F8,0) -> 0 | I8: Serie histórica del SIRSD-S incorporada, consistencia validada contra ODEPA, derivados hidrológicos del modelo de elevación y plan de pruebas documentado
A9: Sprint 3 | B9: 10 a 12 | C9: 12-10-2026 | D9: 30-10-2026 | E9: Módulo de inundaciones y visor terminado | F9: =SUMIFS(Backlog!$D$6:$D$36,Backlog!$F$6:$F$36,$A9,Backlog!$G$6:$G$36,"<>Fuera del compromiso") -> 18 | G9: =SUMIFS(Backlog!$D$6:$D$36,Backlog!$F$6:$F$36,$A9,Backlog!$G$6:$G$36,"Terminada") -> 0 | H9: =IFERROR(G9/F9,0) -> 0 | I9: Índice de susceptibilidad por comuna contrastado con eventos de SENAPRED, exportación de reporte y visor validado en comprensibilidad
A10: Sprint 4 | B10: 13 a 15 | C10: 02-11-2026 | D10: 20-11-2026 | E10: Módulo urbano, validación con usuarios y cierre documental | F10: =SUMIFS(Backlog!$D$6:$D$36,Backlog!$F$6:$F$36,$A10,Backlog!$G$6:$G$36,"<>Fuera del compromiso") -> 24 | G10: =SUMIFS(Backlog!$D$6:$D$36,Backlog!$F$6:$F$36,$A10,Backlog!$G$6:$G$36,"Terminada") -> 0 | H10: =IFERROR(G10/F10,0) -> 0 | I10: Temperatura superficial y déficit de áreas verdes publicados, prueba de usabilidad ejecutada con la contraparte y proceso analítico documentado según CRISP-DM
A11: Cierre | B11: 16 | C11: 23-11-2026 | D11: 24-11-2026 | E11: Congelación, informe y defensa | F11: =SUMIFS(Backlog!$D$6:$D$36,Backlog!$F$6:$F$36,$A11,Backlog!$G$6:$G$36,"<>Fuera del compromiso") -> 0 | G11: =SUMIFS(Backlog!$D$6:$D$36,Backlog!$F$6:$F$36,$A11,Backlog!$G$6:$G$36,"Terminada") -> 0 | H11: =IFERROR(G11/F11,0) -> 0 | I11: Código congelado el viernes 20 de noviembre, informe final entregado y presentación ensayada
A14: Velocidad y holgura
A15: Velocidad estimada al inicio: 25 puntos por sprint. Verificada en los sprints 0 y 1: 26 y 73 puntos, cerca de 50 de promedio.
A16: La velocidad observada no se proyecta hacia adelante: los sprints 0 y 1 avanzaron sobre un prototipo previo y sobre fuentes ya identificadas, mientras que lo que queda depende de fuentes nuevas y de una aprobación externa del USGS.
A17: La épica E7 de modelado predictivo (16 puntos) está clasificada como Could y queda fuera del compromiso. Se aborda solo si el sprint 3 cierra antes de tiempo.

Sheet Hitos
A1: Hitos del calendario
A2: Fechas del cronograma de la asignatura. La fecha de la defensa está por confirmar con la docente guía.
A5: Semana | B5: Fechas | C5: Hito | D5: Tipo | E5: Qué debe estar listo
A6: 4 | B6: 31 ago – 5 sep | C6: Presentación del proyecto | D6: Sumativa Fase 1 | E6: Definición del proyecto, objetivos, metodología, plan de trabajo y evidencias comprometidas.
A7: 6 | B7: 14 – 19 sep | C7: Entrega de objetivos, metodología y cronograma actualizados | D7: Formativa | E7: Esta planilla, el informe corregido y el modelo de proceso actualizado.
A8: 10 | B8: 12 – 17 oct | C8: Evaluación de avance | D8: Formativa | E8: Índice de pertinencia operativo con datos reales y visor navegable. Sin presentación.
A9: 15 | B9: 16 – 21 nov | C9: Presentación del desarrollo y resultados | D9: Sumativa Fase 2 | E9: Sistema completo con los tres módulos. El índice de pertinencia es innegociable; los módulos complementarios se presentan según el criterio de recorte.
A10: 16 | B10: 24 nov | C10: Defensa final | D10: Sumativa Fase 3 | E10: Código congelado el viernes 20 de noviembre. Informe final, resultados y presentación ensayada.
